Error: near line 1: attempt to write a readonly database
Error: near line 1: attempt to write a readonly database
2020-04-02 21:47:08.140531: W tensorflow/stream_executor/platform/default/dso_loader.cc:55] Could not load dynamic library 'libnvinfer.so.6'; dlerror: libnvinfer.so.6: cannot open shared object file: No such file or directory; LD_LIBRARY_PATH: /software/tamusc/Anaconda/3-5.0.0.1/lib:/software/lsf/9.1/linux2.6-glibc2.3-x86_64/lib
2020-04-02 21:47:08.141097: W tensorflow/stream_executor/platform/default/dso_loader.cc:55] Could not load dynamic library 'libnvinfer_plugin.so.6'; dlerror: libnvinfer_plugin.so.6: cannot open shared object file: No such file or directory; LD_LIBRARY_PATH: /software/tamusc/Anaconda/3-5.0.0.1/lib:/software/lsf/9.1/linux2.6-glibc2.3-x86_64/lib
2020-04-02 21:47:08.141126: W tensorflow/compiler/tf2tensorrt/utils/py_utils.cc:30] Cannot dlopen some TensorRT libraries. If you would like to use Nvidia GPU with TensorRT, please make sure the missing libraries mentioned above are installed properly.
2020-04-02 21:47:24.846612: W tensorflow/stream_executor/platform/default/dso_loader.cc:55] Could not load dynamic library 'libcuda.so.1'; dlerror: libcuda.so.1: cannot open shared object file: No such file or directory; LD_LIBRARY_PATH: /software/tamusc/Anaconda/3-5.0.0.1/lib:/software/lsf/9.1/linux2.6-glibc2.3-x86_64/lib
2020-04-02 21:47:24.847587: E tensorflow/stream_executor/cuda/cuda_driver.cc:351] failed call to cuInit: UNKNOWN ERROR (303)
2020-04-02 21:47:24.847666: I tensorflow/stream_executor/cuda/cuda_diagnostics.cc:156] kernel driver does not appear to be running on this host (lrg256-3005): /proc/driver/nvidia/version does not exist
2020-04-02 21:47:24.859075: I tensorflow/core/platform/profile_utils/cpu_utils.cc:94] CPU Frequency: 2499940000 Hz
2020-04-02 21:47:24.860421: I tensorflow/compiler/xla/service/service.cc:168] XLA service 0x56135046a840 initialized for platform Host (this does not guarantee that XLA will be used). Devices:
2020-04-02 21:47:24.860457: I tensorflow/compiler/xla/service/service.cc:176]   StreamExecutor device (0): Host, Default Version
Using TensorFlow backend.
Running Cutting veggies classifier
Categories:  ['Cutting', 'NotCutting']
Loading images...
Traceback (most recent call last):
  File "classify.py", line 184, in <module>
    train_x, val_x, test_x, train_y, val_y, test_y, classweight, classes = load_data(NUM_CLASSES, IMG_HEIGHT, IMG_WIDTH, seed=7, root_dir=data_dir)
  File "classify.py", line 146, in load_data
    train_x = read_from_paths(train_path)
  File "classify.py", line 111, in read_from_paths
    img = load_img(path, target_size=(IMG_HEIGHT, IMG_WIDTH))
  File "/scratch/user/skumar55/.conda/envs/kumarenv/lib/python3.5/site-packages/keras_preprocessing/image/utils.py", line 110, in load_img
    img = pil_image.open(path)
  File "/scratch/user/skumar55/.conda/envs/kumarenv/lib/python3.5/site-packages/PIL/Image.py", line 2548, in open
    fp = builtins.open(filename, "rb")
KeyboardInterrupt
